<?xml version="1.0" encoding="utf-8" ?>
<!-- This URDF was automatically created by SolidWorks to URDF Exporter! Originally created by Stephen Brawner (brawner@gmail.com) 
     Commit Version: 1.6.0-4-g7f85cfe  Build Version: 1.6.7995.38578
     For more information, please see http://wiki.ros.org/sw_urdf_exporter -->
<robot name="manipulator_arm">
    <link name="world" />
    <joint name="base_joint" type="fixed">
        <parent link="world" />
        <child link="base_link" />
        <origin rpy="0 0 0" xyz="-0.12 0.27 0.0" />
    </joint>
    <link name="base_link">
        <inertial>
            <origin xyz="0.097626 0.062093 0.22842" rpy="0 0 0" />
            <mass value="3.5599" />
            <inertia ixx="0.019304" ixy="-5.9075E-10" ixz="-1.2193E-09" iyy="0.019916" iyz="0.00018367" izz="0.012646" />
        </inertial>
        <visual>
            <origin xyz="0 0 0" rpy="0 0 0" />
            <geometry>
                <mesh filename="package://manipulator_arm/meshes/base_link.STL" />
            </geometry>
            <material name="">
                <color rgba="0.12157 0.12157 0.12157 1" />
            </material>
        </visual>
        <collision>
            <origin xyz="0 0 0" rpy="0 0 0" />
            <geometry>
                <mesh filename="package://manipulator_arm/meshes/base_link.STL" />
            </geometry>
        </collision>
    </link>
    <link name="link_1">
        <inertial>
            <origin xyz="-0.019755 4.427E-15 0.077605" rpy="0 0 0" />
            <mass value="1.375" />
            <inertia ixx="0.0056845" ixy="6.1339E-17" ixz="0.0016247" iyy="0.00679" iyz="-1.265E-16" izz="0.0073809" />
        </inertial>
        <visual>
            <origin xyz="0 0 0" rpy="0 0 0" />
            <geometry>
                <mesh filename="package://manipulator_arm/meshes/link_1.STL" />
            </geometry>
            <material name="">
                <color rgba="0.12157 0.12157 0.12157 1" />
            </material>
        </visual>
        <collision>
            <origin xyz="0 0 0" rpy="0 0 0" />
            <geometry>
                <mesh filename="package://manipulator_arm/meshes/link_1.STL" />
            </geometry>
        </collision>
    </link>
    <joint name="joint_1" type="revolute">
        <origin xyz="0.097626 -0.27119 0.1327" rpy="0 0 1.5613" />
        <parent link="base_link" />
        <child link="link_1" />
        <axis xyz="0 0 1" />
        <limit lower="0" upper="6.284" effort="300" velocity="3" />
    </joint>
    <link name="link_2">
        <inertial>
            <origin xyz="0.086535 1.3548E-08 -0.002" rpy="0 0 0" />
            <mass value="0.63532" />
            <inertia ixx="0.0020892" ixy="-7.3508E-11" ixz="-6.987E-19" iyy="0.006396" iyz="4.845E-19" izz="0.0068078" />
        </inertial>
        <visual>
            <origin xyz="0 0 0" rpy="0 0 0" />
            <geometry>
                <mesh filename="package://manipulator_arm/meshes/link_2.STL" />
            </geometry>
            <material name="">
                <color rgba="0.82745 0.69804 0.4902 1" />
            </material>
        </visual>
        <collision>
            <origin xyz="0 0 0" rpy="0 0 0" />
            <geometry>
                <mesh filename="package://manipulator_arm/meshes/link_2.STL" />
            </geometry>
        </collision>
    </link>
    <joint name="joint_2" type="revolute">
        <origin xyz="0 0 0.16671" rpy="-1.5708 -1.5434 3.1416" />
        <parent link="link_1" />
        <child link="link_2" />
        <axis xyz="0 0 1" />
        <limit lower="-1.47" upper="1.12" effort="200" velocity="3" />
    </joint>
    <link name="link_3">
        <inertial>
            <origin xyz="0.09086 -2.2204E-16 6.9389E-17" rpy="0 0 0" />
            <mass value="0.58657" />
            <inertia ixx="0.00079015" ixy="5.8039E-18" ixz="8.6397E-19" iyy="0.002143" iyz="-1.5829E-20" izz="0.0023438" />
        </inertial>
        <visual>
            <origin xyz="0 0 0" rpy="0 0 0" />
            <geometry>
                <mesh filename="package://manipulator_arm/meshes/link_3.STL" />
            </geometry>
            <material name="">
                <color rgba="0.82745 0.69804 0.4902 1" />
            </material>
        </visual>
        <collision>
            <origin xyz="0 0 0" rpy="0 0 0" />
            <geometry>
                <mesh filename="package://manipulator_arm/meshes/link_3.STL" />
            </geometry>
        </collision>
    </link>
    <joint name="joint_3" type="revolute">
        <origin xyz="0.25 0 0" rpy="3.1416 0 -1.5571" />
        <parent link="link_2" />
        <child link="link_3" />
        <axis xyz="0 0 1" />
        <limit lower="-3.142" upper="0" effort="200" velocity="3" />
    </joint>
    <link name="link_4">
        <inertial>
            <origin xyz="0.00050485 2.2204E-16 0.0015" rpy="0 0 0" />
            <mass value="0.1502" />
            <inertia ixx="8.1788E-05" ixy="3.7269E-20" ixz="6.0351E-21" iyy="8.2469E-05" iyz="9.5821E-21" izz="0.00013749" />
        </inertial>
        <visual>
            <origin xyz="0 0 0" rpy="0 0 0" />
            <geometry>
                <mesh filename="package://manipulator_arm/meshes/link_4.STL" />
            </geometry>
            <material name="">
                <color rgba="0.82745 0.69804 0.4902 1" />
            </material>
        </visual>
        <collision>
            <origin xyz="0 0 0" rpy="0 0 0" />
            <geometry>
                <mesh filename="package://manipulator_arm/meshes/link_4.STL" />
            </geometry>
        </collision>
    </link>
    <joint name="joint_4" type="revolute">
        <origin xyz="0.16 0 0" rpy="-3.1416 0 0.15302" />
        <parent link="link_3" />
        <child link="link_4" />
        <axis xyz="0 0 1" />
        <limit lower="-1.35" upper="1.35" effort="200" velocity="3" />
    </joint>
    <link name="link_5">
        <inertial>
            <origin xyz="-3.3307E-16 2.498E-16 0.02691" rpy="0 0 0" />
            <mass value="0.14945" />
            <inertia ixx="7.1409E-05" ixy="-3.9175E-21" ixz="-4.1081E-20" iyy="7.1409E-05" iyz="1.7364E-20" izz="0.00012043" />
        </inertial>
        <visual>
            <origin xyz="0 0 0" rpy="0 0 0" />
            <geometry>
                <mesh filename="package://manipulator_arm/meshes/link_5.STL" />
            </geometry>
            <material name="">
                <color rgba="0.12157 0.12157 0.12157 1" />
            </material>
        </visual>
        <collision>
            <origin xyz="0 0 0" rpy="0 0 0" />
            <geometry>
                <mesh filename="package://manipulator_arm/meshes/link_5.STL" />
            </geometry>
        </collision>
    </link>
    <joint name="joint_5" type="revolute">
        <origin xyz="0.030136 0 0.0015" rpy="-1.5708 0.57462 -1.5708" />
        <parent link="link_4" />
        <child link="link_5" />
        <axis xyz="0 0 1" />
        <limit lower="0" upper="3.142" effort="200" velocity="3" />
    </joint>
    <transmission name="link_1_trans">
        <type>transmission_interface/SimpleTransmission</type>
        <joint name="joint_1">
            <hardwareInterface>hardware_interface/PositionJointInterface</hardwareInterface>
        </joint>
        <actuator name="link_1_motor">
            <hardwareInterface>hardware_interface/PositionJointInterface</hardwareInterface>
            <mechanicalReduction>1</mechanicalReduction>
        </actuator>
    </transmission>
    <transmission name="link_2_trans">
        <type>transmission_interface/SimpleTransmission</type>
        <joint name="joint_2">
            <hardwareInterface>hardware_interface/PositionJointInterface</hardwareInterface>
        </joint>
        <actuator name="link_2_motor">
            <hardwareInterface>hardware_interface/PositionJointInterface</hardwareInterface>
            <mechanicalReduction>1</mechanicalReduction>
        </actuator>
    </transmission>
    <transmission name="link_3_trans">
        <type>transmission_interface/SimpleTransmission</type>
        <joint name="joint_3">
            <hardwareInterface>hardware_interface/PositionJointInterface</hardwareInterface>
        </joint>
        <actuator name="link_3_motor">
            <hardwareInterface>hardware_interface/PositionJointInterface</hardwareInterface>
            <mechanicalReduction>1</mechanicalReduction>
        </actuator>
    </transmission>
    <transmission name="link_4_trans">
        <type>transmission_interface/SimpleTransmission</type>
        <joint name="joint_4">
            <hardwareInterface>hardware_interface/PositionJointInterface</hardwareInterface>
        </joint>
        <actuator name="link_4_motor">
            <hardwareInterface>hardware_interface/PositionJointInterface</hardwareInterface>
            <mechanicalReduction>1</mechanicalReduction>
        </actuator>
    </transmission>
    <transmission name="link_5_trans">
        <type>transmission_interface/SimpleTransmission</type>
        <joint name="joint_5">
            <hardwareInterface>hardware_interface/PositionJointInterface</hardwareInterface>
        </joint>
        <actuator name="link_5_motor">
            <hardwareInterface>hardware_interface/PositionJointInterface</hardwareInterface>
            <mechanicalReduction>1</mechanicalReduction>
        </actuator>
    </transmission>
    <gazebo>
        <plugin name="control" filename="libgazebo_ros_control.so">
            <robotNamespace>/</robotNamespace>
        </plugin>
        <plugin name="gazebo_ros_control">
            <robotNamespace>/</robotNamespace>
        </plugin>
    </gazebo>
    <gazebo reference="link_1">
        <selfCollide>true</selfCollide>
    </gazebo>
    <gazebo reference="link_2">
        <selfCollide>true</selfCollide>
    </gazebo>
    <gazebo reference="link_3">
        <selfCollide>true</selfCollide>
    </gazebo>
    <gazebo reference="link_4">
        <selfCollide>true</selfCollide>
    </gazebo>
    <gazebo reference="link_5">
        <selfCollide>true</selfCollide>
    </gazebo>
</robot>

